<?xml version="1.0"?>
<robot xmlns:xacro="http://wiki.ros.org/wiki/xacro" name="ddrive">

<xacro:include filename="$(find diff_drive)/urdf/ddrive.gazebo.xacro"/>

<xacro:property name="ddrive" value="$(find diff_drive)/config/ddrive.yaml" />
<xacro:property name="config" value="${load_yaml(ddrive)}" />

<xacro:property name="box_l" value="${config['box_l']}" />
<xacro:property name="box_w" value="${config['box_w']}" />
<xacro:property name="box_h" value="${config['box_h']}" />
<xacro:property name="box_m" value="${config['box_m']}" />
<xacro:property name="wheel_h" value="${config['wheel_h']}" />
<xacro:property name="wheel_r" value="${config['wheel_r']}" />
<xacro:property name="wheel_m" value="${config['wheel_m']}" />
<xacro:property name="caster_r" value="${config['caster_r']}" />
<xacro:property name="caster_m" value="${config['caster_m']}" />


<material name="black">
    <color rgba="0 0 0 1"/>
</material>
<material name="gray">
    <color rgba="0.3 0.3 0.3 1" />
</material>

<link name="base_link" />

<joint name ="base" type="fixed">
    <origin xyz="0 0 0" rpy="0 0 0" />
    <parent link="base_link" />
    <child link="chassis" />
</joint>

<link name="chassis">
    <visual>
        <origin rpy="0 0 0" xyz="0 0 0" />
        <geometry>
            <box size="${box_l} ${box_w} ${box_h}" />
        </geometry>
        <material name="black"/>
    </visual>

    <collision>
        <origin rpy="0 0 0" xyz="0 0 0" />
        <geometry>
            <box size="${box_l} ${box_w} ${box_h}"/>
        </geometry>
    </collision>

    <inertial>
        <origin rpy="0 0 0" xyz="0 0 0" />
        <mass value="${box_m}" />
        <inertia ixx="${1/12*box_m*(box_h**2 + box_l**2)}" ixy="0.0" ixz="0.0"
                 iyy="${1/12*box_m*(box_h**2 + box_l**2)}" iyz="0.0"
                 izz="${1/12*box_m*(box_w**2 + box_h**2)}"/>
    </inertial>

</link>

<joint name="wheel_right" type="continuous">
    <axis xyz="0 1 0" />
    <origin xyz="0.1875 -0.17 0" rpy="0 0 0" />
    <parent link="chassis" />
    <child link="right_wheel" />
</joint>

<link name="right_wheel">
    <visual>
    <origin rpy="0 ${pi/2} ${pi/2}" xyz="0 0 0" />
        <geometry>
            <cylinder length="${wheel_h}" radius="${wheel_r}"/>
        </geometry>
        <material name="gray"/>
        <inertial>
           <mass value="${wheel_m}"/>
           <origin rpy="0 0 0" xyz="0 0 0" />
           <inertia ixx="1/12*${wheel_m}*(3*${wheel_r}**2 + ${wheel_h}**2)" ixy="0.0" ixz="0.0" iyy="1/12*${wheel_m}*(3*${wheel_r}**2 + ${wheel_h}**2)" iyz="0.0" izz="1/2*${wheel_m}*${wheel_r}**2"/>
         </inertial>
    </visual>
    <collision>
        <origin rpy="0 0 0" xyz="0 0 0" />
        <geometry>
            <cylinder length="${wheel_h}" radius="${wheel_r}"/>
        </geometry>
    </collision>
</link>

<joint name="wheel_left" type="continuous">
    <axis xyz="0 1 0" />
    <origin xyz="0.1875 0.17 0" rpy="0 0 0" />
    <parent link="chassis" />
    <child link="left_wheel" />
</joint>

<link name="left_wheel">
    <visual>
    <origin rpy="0 ${pi/2} ${pi/2}" xyz="0 0 0" />
        <geometry>
            <cylinder length="${wheel_h}" radius="${wheel_r}"/>
        </geometry>
        <material name="gray"/>
        <inertial>
           <mass value="0.2"/>
           <origin rpy="0 0 0" xyz="0 0 0" />
           <inertia ixx="1/12*${wheel_m}*(3*${wheel_r}**2 + ${wheel_h}**2)" ixy="0.0" ixz="0.0" iyy="1/12*${wheel_m}*(3*${wheel_r}**2 + ${wheel_h}**2)" iyz="0.0" izz="1/2*${wheel_m}*${wheel_r}**2"/>
         </inertial>
    </visual>
    <collision>
        <origin rpy="0 0 0" xyz="0 0 0" />
        <geometry>
            <cylinder length="${wheel_h}" radius="${wheel_r}"/>
        </geometry>
    </collision>
</link>

<joint name="caster_top" type="fixed">
    <origin xyz="-0.1875 0 0.1" rpy="0 0 0" />
    <parent link="chassis" />
    <child link="top_caster" />
</joint>

<link name="top_caster">
    <visual>
    <origin rpy="${pi/2} 0 0" xyz="0 0 0" />
        <geometry>
            <sphere radius="${caster_r}"/>
        </geometry>
        <material name="gray"/>
        <inertial>
           <mass value="${caster_m}"/>
           <origin xyz="0 0 0" />
           <inertia ixx="2/5*${caster_m}*(${caster_r}**2)" ixy="0.0" ixz="0.0" iyy="2/5*${caster_m}*(${caster_r}**2)" iyz="0.0" izz="2/5*${caster_m}*${caster_r}**2"/>
         </inertial>
    </visual>
    <collision>
        <origin rpy="${pi/2} 0 0" xyz="0 0 0" />
        <geometry>
            <sphere radius="${caster_r}"/>
        </geometry>
    </collision>
</link>

<joint name="caster_bottom" type="fixed">
    <origin xyz="-0.1875 0 -0.1" rpy="0 0 0" />
    <parent link="chassis" />
    <child link="bottom_caster" />
</joint>

<link name="bottom_caster">
    <visual>
    <origin rpy="${pi/2} 0 0" xyz="0 0 0" />
        <geometry>
            <sphere radius="${caster_r}"/>
        </geometry>
        <material name="gray"/>
        <inertial>
           <mass value="0.05"/>
           <origin xyz="0 0 0" />
           <inertia ixx="2/5*${caster_m}*(${caster_r}**2)" ixy="0.0" ixz="0.0" iyy="2/5*${caster_m}*(${caster_r}**2)" iyz="0.0" izz="2/5*${caster_m}*${caster_r}**2"/>
         </inertial>
    </visual>
    <collision>
        <origin rpy="${pi/2} 0 0" xyz="0 0 0" />
        <geometry>
            <sphere radius="${caster_r}"/>
        </geometry>
    </collision>
</link>

</robot>